<?xml version="1.0"?>
<robot name="dagu_wild_thumper">
  <link name="base_link">
    <visual>
      <geometry>
        <box size="0.4 0.5 0.2"/>
        <origin xyz="0 0 .2" rpy="0 0 0"/>
      </geometry>
    </visual>
  </link>
    <link name="left_wheel">
        <visual>
        <geometry>
            <cylinder length="0.1" radius="0.1"/>
            <origin xyz="0.25 0 0" rpy="0 0 0"/>
        </geometry>
        </visual>
    </link>
    <joint name="left_wheel_joint" type="continuous">
        <parent link="base_link"/>
        <child link="left_wheel"/>
        <origin xyz="0.25 0 0" rpy="0 1.57075 0"/>
        <axis xyz="0 0 1"/>
        </joint>

    <link name="right_wheel">
        <visual>
        <geometry>
            <cylinder length="0.1" radius="0.1"/>
        </geometry>
        </visual>
        <origin xyz="-0.25 0 0" rpy="0 0 0"/>
    </link>
    <joint name="right_wheel_joint" type="continuous">
        <parent link="base_link"/>
        <child link="right_wheel"/>
        <origin xyz="-0.25 0 0" rpy="0 1.57075 0"/>
        <axis xyz="0 0 1"/>
    </joint>

</robot>